2021-12-20 18:52:50,404 DEBUG    root            Loaded Command Group: ['gcloud', 'sql']
2021-12-20 18:52:50,436 DEBUG    root            Loaded Command Group: ['gcloud', 'sql', 'connect']
2021-12-20 18:52:50,442 DEBUG    root            Running [gcloud.sql.connect] with arguments: [--user: "postgres", INSTANCE: "app-database"]
2021-12-20 18:52:50,455 DEBUG    google.auth.transport.requests Making request: GET http://metadata.google.internal/computeMetadata/v1/instance/service-accounts/712862630822-compute@developer.gserviceaccount.com/?recursive=true
2021-12-20 18:52:50,457 DEBUG    urllib3.connectionpool Starting new HTTP connection (1): metadata.google.internal:80
2021-12-20 18:52:50,459 DEBUG    urllib3.connectionpool http://metadata.google.internal:80 "GET /computeMetadata/v1/instance/service-accounts/712862630822-compute@developer.gserviceaccount.com/?recursive=true HTTP/1.1" 200 207
2021-12-20 18:52:50,460 DEBUG    google.auth.transport.requests Making request: GET http://metadata.google.internal/computeMetadata/v1/instance/service-accounts/712862630822-compute@developer.gserviceaccount.com/token
2021-12-20 18:52:50,462 DEBUG    urllib3.connectionpool http://metadata.google.internal:80 "GET /computeMetadata/v1/instance/service-accounts/712862630822-compute@developer.gserviceaccount.com/token HTTP/1.1" 200 269
2021-12-20 18:52:50,493 DEBUG    google.auth.transport.requests Making request: GET http://metadata.google.internal/computeMetadata/v1/instance/service-accounts/712862630822-compute@developer.gserviceaccount.com/?recursive=true
2021-12-20 18:52:50,494 DEBUG    urllib3.connectionpool Starting new HTTP connection (1): metadata.google.internal:80
2021-12-20 18:52:50,496 DEBUG    urllib3.connectionpool http://metadata.google.internal:80 "GET /computeMetadata/v1/instance/service-accounts/712862630822-compute@developer.gserviceaccount.com/?recursive=true HTTP/1.1" 200 207
2021-12-20 18:52:50,496 DEBUG    google.auth.transport.requests Making request: GET http://metadata.google.internal/computeMetadata/v1/instance/service-accounts/712862630822-compute@developer.gserviceaccount.com/token
2021-12-20 18:52:50,499 DEBUG    urllib3.connectionpool http://metadata.google.internal:80 "GET /computeMetadata/v1/instance/service-accounts/712862630822-compute@developer.gserviceaccount.com/token HTTP/1.1" 200 269
2021-12-20 18:52:50,510 DEBUG    urllib3.connectionpool Starting new HTTPS connection (1): sqladmin.googleapis.com:443
2021-12-20 18:52:50,632 DEBUG    urllib3.connectionpool https://sqladmin.googleapis.com:443 "GET /sql/v1beta4/projects/analog-bot-325915/instances/app-database?alt=json HTTP/1.1" 200 None
2021-12-20 18:52:50,948 DEBUG    urllib3.connectionpool https://sqladmin.googleapis.com:443 "PATCH /sql/v1beta4/projects/analog-bot-325915/instances/app-database?alt=json HTTP/1.1" 409 None
2021-12-20 18:52:50,949 WARNING  root            If you're connecting from an IPv6 address, or are constrained by certain organization policies (restrictPublicIP, restrictAuthorizedNetworks), consider running the beta version of this command by connecting through the Cloud SQL proxy: gcloud beta sql connect
2021-12-20 18:52:50,950 DEBUG    root            (gcloud.sql.connect) HTTPError 409: Operation failed because another operation was already in progress.
Traceback (most recent call last):
  File "/usr/lib/google-cloud-sdk/lib/surface/sql/connect.py", line 144, in _AllowlistClientIP
    result = sql_client.instances.Patch(patch_request)
  File "/usr/lib/google-cloud-sdk/lib/googlecloudsdk/third_party/apis/sqladmin/v1beta4/sqladmin_v1beta4_client.py", line 739, in Patch
    config, request, global_params=global_params)
  File "/usr/bin/../lib/google-cloud-sdk/lib/third_party/apitools/base/py/base_api.py", line 737, in _RunMethod
    return self.ProcessHttpResponse(method_config, http_response, request)
  File "/usr/bin/../lib/google-cloud-sdk/lib/third_party/apitools/base/py/base_api.py", line 743, in ProcessHttpResponse
    self.__ProcessHttpResponse(method_config, http_response, request))
  File "/usr/bin/../lib/google-cloud-sdk/lib/third_party/apitools/base/py/base_api.py", line 610, in __ProcessHttpResponse
    http_response, method_config=method_config, request=request)
apitools.base.py.exceptions.HttpConflictError: HttpError accessing <https://sqladmin.googleapis.com/sql/v1beta4/projects/analog-bot-325915/instances/app-database?alt=json>: response: <{'vary': 'Origin, X-Origin, Referer', 'content-type': 'application/json; charset=UTF-8', 'content-encoding': 'gzip', 'date': 'Mon, 20 Dec 2021 18:52:50 GMT', 'server': 'ESF', 'cache-control': 'private', 'x-xss-protection': '0', 'x-frame-options': 'SAMEORIGIN', 'x-content-type-options': 'nosniff', 'transfer-encoding': 'chunked', 'status': 409}>, content <{
  "error": {
    "code": 409,
    "message": "Operation failed because another operation was already in progress.",
    "errors": [
      {
        "message": "Operation failed because another operation was already in progress.",
        "domain": "global",
        "reason": "operationInProgress"
      }
    ]
  }
}
>

During handling of the above exception, another exception occurred:

Traceback (most recent call last):
  File "/usr/lib/google-cloud-sdk/lib/googlecloudsdk/calliope/cli.py", line 987, in Execute
    resources = calliope_command.Run(cli=self, args=args)
  File "/usr/lib/google-cloud-sdk/lib/googlecloudsdk/calliope/backend.py", line 809, in Run
    resources = command_instance.Run(args)
  File "/usr/lib/google-cloud-sdk/lib/surface/sql/connect.py", line 393, in Run
    return RunConnectCommand(args, supports_database=True)
  File "/usr/lib/google-cloud-sdk/lib/surface/sql/connect.py", line 238, in RunConnectCommand
    client.resource_parser)
  File "/usr/lib/google-cloud-sdk/lib/surface/sql/connect.py", line 152, in _AllowlistClientIP
    raise calliope_exceptions.HttpException(error)
googlecloudsdk.calliope.exceptions.HttpException: HTTPError 409: Operation failed because another operation was already in progress.
2021-12-20 18:52:50,952 ERROR    root            (gcloud.sql.connect) HTTPError 409: Operation failed because another operation was already in progress.
