2022-01-10 10:55:55,415 DEBUG    root            Loaded Command Group: ['gcloud', 'sql']
2022-01-10 10:55:55,441 DEBUG    root            Loaded Command Group: ['gcloud', 'sql', 'connect']
2022-01-10 10:55:55,449 DEBUG    root            Running [gcloud.sql.connect] with arguments: [--user: "postgres", INSTANCE: "app-database"]
2022-01-10 10:55:55,461 DEBUG    google.auth.transport.requests Making request: GET http://metadata.google.internal/computeMetadata/v1/instance/service-accounts/712862630822-compute@developer.gserviceaccount.com/?recursive=true
2022-01-10 10:55:55,463 DEBUG    urllib3.connectionpool Starting new HTTP connection (1): metadata.google.internal:80
2022-01-10 10:55:55,464 DEBUG    urllib3.connectionpool http://metadata.google.internal:80 "GET /computeMetadata/v1/instance/service-accounts/712862630822-compute@developer.gserviceaccount.com/?recursive=true HTTP/1.1" 200 207
2022-01-10 10:55:55,465 DEBUG    google.auth.transport.requests Making request: GET http://metadata.google.internal/computeMetadata/v1/instance/service-accounts/712862630822-compute@developer.gserviceaccount.com/token
2022-01-10 10:55:55,467 DEBUG    urllib3.connectionpool http://metadata.google.internal:80 "GET /computeMetadata/v1/instance/service-accounts/712862630822-compute@developer.gserviceaccount.com/token HTTP/1.1" 200 276
2022-01-10 10:55:55,487 DEBUG    google.auth.transport.requests Making request: GET http://metadata.google.internal/computeMetadata/v1/instance/service-accounts/712862630822-compute@developer.gserviceaccount.com/?recursive=true
2022-01-10 10:55:55,489 DEBUG    urllib3.connectionpool Starting new HTTP connection (1): metadata.google.internal:80
2022-01-10 10:55:55,490 DEBUG    urllib3.connectionpool http://metadata.google.internal:80 "GET /computeMetadata/v1/instance/service-accounts/712862630822-compute@developer.gserviceaccount.com/?recursive=true HTTP/1.1" 200 207
2022-01-10 10:55:55,491 DEBUG    google.auth.transport.requests Making request: GET http://metadata.google.internal/computeMetadata/v1/instance/service-accounts/712862630822-compute@developer.gserviceaccount.com/token
2022-01-10 10:55:55,492 DEBUG    urllib3.connectionpool http://metadata.google.internal:80 "GET /computeMetadata/v1/instance/service-accounts/712862630822-compute@developer.gserviceaccount.com/token HTTP/1.1" 200 276
2022-01-10 10:55:55,503 DEBUG    urllib3.connectionpool Starting new HTTPS connection (1): sqladmin.googleapis.com:443
2022-01-10 10:55:55,586 DEBUG    urllib3.connectionpool https://sqladmin.googleapis.com:443 "GET /sql/v1beta4/projects/analog-bot-325915/instances/app-database?alt=json HTTP/1.1" 404 None
2022-01-10 10:55:55,587 DEBUG    root            (gcloud.sql.connect) HTTPError 404: The Cloud SQL instance does not exist.
Traceback (most recent call last):
  File "/usr/lib/google-cloud-sdk/lib/surface/sql/connect.py", line 127, in _AllowlistClientIP
    project=instance_ref.project, instance=instance_ref.instance))
  File "/usr/lib/google-cloud-sdk/lib/googlecloudsdk/third_party/apis/sqladmin/v1beta4/sqladmin_v1beta4_client.py", line 609, in Get
    config, request, global_params=global_params)
  File "/usr/bin/../lib/google-cloud-sdk/lib/third_party/apitools/base/py/base_api.py", line 737, in _RunMethod
    return self.ProcessHttpResponse(method_config, http_response, request)
  File "/usr/bin/../lib/google-cloud-sdk/lib/third_party/apitools/base/py/base_api.py", line 743, in ProcessHttpResponse
    self.__ProcessHttpResponse(method_config, http_response, request))
  File "/usr/bin/../lib/google-cloud-sdk/lib/third_party/apitools/base/py/base_api.py", line 610, in __ProcessHttpResponse
    http_response, method_config=method_config, request=request)
apitools.base.py.exceptions.HttpNotFoundError: HttpError accessing <https://sqladmin.googleapis.com/sql/v1beta4/projects/analog-bot-325915/instances/app-database?alt=json>: response: <{'vary': 'Origin, X-Origin, Referer', 'content-type': 'application/json; charset=UTF-8', 'content-encoding': 'gzip', 'date': 'Mon, 10 Jan 2022 10:55:55 GMT', 'server': 'ESF', 'cache-control': 'private', 'x-xss-protection': '0', 'x-frame-options': 'SAMEORIGIN', 'x-content-type-options': 'nosniff', 'transfer-encoding': 'chunked', 'status': 404}>, content <{
  "error": {
    "code": 404,
    "message": "The Cloud SQL instance does not exist.",
    "errors": [
      {
        "message": "The Cloud SQL instance does not exist.",
        "domain": "global",
        "reason": "instanceDoesNotExist"
      }
    ]
  }
}
>

During handling of the above exception, another exception occurred:

Traceback (most recent call last):
  File "/usr/lib/google-cloud-sdk/lib/googlecloudsdk/calliope/cli.py", line 987, in Execute
    resources = calliope_command.Run(cli=self, args=args)
  File "/usr/lib/google-cloud-sdk/lib/googlecloudsdk/calliope/backend.py", line 809, in Run
    resources = command_instance.Run(args)
  File "/usr/lib/google-cloud-sdk/lib/surface/sql/connect.py", line 393, in Run
    return RunConnectCommand(args, supports_database=True)
  File "/usr/lib/google-cloud-sdk/lib/surface/sql/connect.py", line 238, in RunConnectCommand
    client.resource_parser)
  File "/usr/lib/google-cloud-sdk/lib/surface/sql/connect.py", line 133, in _AllowlistClientIP
    raise calliope_exceptions.HttpException(error)
googlecloudsdk.calliope.exceptions.HttpException: HTTPError 404: The Cloud SQL instance does not exist.
2022-01-10 10:55:55,594 ERROR    root            (gcloud.sql.connect) HTTPError 404: The Cloud SQL instance does not exist.
